Workbook

Sheet AI指令
A1: 你是一名经验丰富的亚马逊美国站运营专家，精通 A9 / A10（搜索排名与广告）、Cosmo（基于用户画像的个性化排序）、Rufus（生成式 AI 购物助手）及Alexa for Shopping的算法逻辑。我将为你提供： 1.我们新品的中英文名称； 2.我们自己的产品图片（通常与竞品几乎一样，如有差异会单独标注）； 3.竞品的 Listing 文案（标题/五点/描述）以及竞品的评论汇总（包含好评与差评）； 4.（可选）竞品或 Google 的相关链接。如果我没有提供链接中的关键文本，请根据你自身知识库中的同类产品常识进行推测，并会明确标注“基于知识库推测”。 5.关键词和词频表 重要说明： 由于是新品，我们暂无自己的转化数据或历史评论。你需要基于竞品文案和评论，结合我们自己产品的差异点，写出不抄袭、更优、更合规的 Listing。 要求： 1.语言地道本土化、生动详细有创新性和购买欲，符合美国消费者阅读习惯与搜索意图。文案中需自然埋入高频搜索词和长尾词，并指出避免堆砌，同时规避任何侵权词、敏感词、违规词等 2.严禁直接复制竞品文案，只能提取事实参数（如尺寸、材质、重量）并用自己的话重组。 不要完全照抄同行的内容，不要胡编乱造，不确定的地方标记备注出来。3. 3.标题≤200 字符，五点属性每行≤500字符，产品描述内容≤2000 字符，后台搜索关键词≤250 字符。 4.产品描述内容≤2000 字符需要基于现有的五点内容，拓展出多样化的内容，例如第1段回答 Rufus 问题 + 第2段埋 A10 关键词 + 第3段打 Cosmo 人群标签 + 第4段建信任 + 第5段写 Alexa 语音词。 处理不确定信息： 1.如果竞品或评论中缺乏我们产品某个特性的明确依据（例如：是否防水、适配某型号），请用 [需要确认：xxx] 标注。 2.如果我们自己产品的图片与竞品存在差异，你会额外告诉我差异点，我会按这些差异调整文案（例如材质升级、颜色不同等）。 3.如果无法抓取链接内容，请根据你的知识库提供合理推测，并注明“基于同类产品”。 工作流程 你先回复：“已收到文件，分析完成后将输出优化方案。” 等我确认后，你再开始分析与撰写。 在我上传所有文件（图片、竞品文案、评论汇总、差异点说明）之前，请勿输出具体文案，只等待指令。

Sheet 文案
B1: 竞对 | D1: 标题 | F1: 五点 | J1: 辅助信息 | K1: A | L1: 标题 | P1: 五点
A2: 1 | B2: =_xlfn.DISPIMG("ID_F45B1D04DFA241D39E656D7C6131293D",1) -> =DISPIMG("ID_F45B1D04DFA241D39E656D7C6131293D",1) | C2: B0GG3Q92LS | D2: Nilight Wireless Magnetic RGB LED Interior Lights, 4 PCS 7 Colors USB Rechargeable Universal Mini Sticky Footwell Ambient Atmosphere Reading Lamp with Touch Sensor, Portable Night Lighting for Car | E2: =LEN(D2) -> 196 | F2: 7-Color RGB Car Light: Equipped with 6PCS RGB LED chips, allows touch-switching between 7 vivid colors—red, green, blue, yellow, purple, ice blue, and white. Provides non-dazzling, targeted lighting to clearly illuminate interior details without distracting the driver, enhancing driving safety Touch-Control Design: Tap to turn on or switch lighting effects,press and hold for 3 seconds to turn off.Easy to operate.Note: Please charge before first use. The switch may be accidentally activated during shipping, potentially draining the battery Easy Installation: Attach the metal plate with double-sided tape to the mounting surface, then stick the magnetic sheet to the light; the light will be pulled into place by the magnets as you bring it close—quick setup and effortless removal. The magnetic design also allows flexible placement on any metal surface in the car Portable & USB Rechargeable: Compact and space-saving design. Light charges via Micro-B USB cable in just 30 minutes, providing 1.5–3.5 hours of illumination. A blue indicator lights up during charging and turns off when fully charged Wide Application: It can be installed in cars of dim areas, such as storage boxes, footwell, cupholder, trunk, armrest compartments, car doors, and seat corners. Not only for vehicles but also for home use—ideal as a bedside, wardrobe, or reading light. Place it anywhere to brighten up dark spaces, offering flexible installation wherever needed | G2: =LEN(F2) -> 1452 | H2: 7色RGB汽车灯：配备6颗RGB LED芯片，支持触控切换7种鲜艳色彩——红、绿、蓝、黄、紫、冰蓝和白色。采用非眩光定向照明技术，能清晰照亮车内细节而不分散驾驶员注意力，提升行车安全性。 触控设计：轻触即可开启或切换灯光效果，长按3秒即可关闭，操作简便。注意：首次使用前请充电。开关在运输过程中可能意外激活，导致电池耗电。 简易安装：用双面胶将金属板固定于安装表面，再将磁性片贴合灯具；靠近时磁铁会自动定位灯具——快速安装且轻松拆卸。磁吸设计可灵活放置于车内任何金属表面。 便携式USB可充电：紧凑节省空间的设计。通过Micro-B USB线缆仅需30分钟即可完成充电，提供1.5至3.5小时照明时间。充电时蓝色指示灯亮起，充满后熄灭。 广泛适用场景：可安装于车辆暗区，如储物箱、脚踏板、杯架、后备箱、扶手隔层、车门及座椅角落。不仅适用于汽车，也可用于家庭场景——作为床头灯、衣柜灯或阅读灯非常理想。可随意摆放于黑暗区域，为环境增添明亮感。 | I2: 我们的产品信息→ | K2: A60401-SL-USFBA | L2: 4Pcs Magnetic LED Interior Car Lights – 8 Colors RGB Wireless Ambient Lighting with Remote & Touch Control, USB Rechargeable Portable Strobe Nightlight for Footwell Door Dash Glove Box – Car Truck SUV | M2: =LEN(L2) -> 200
A3: 2 | B3: =_xlfn.DISPIMG("ID_FCC82BBAA3A241A297D8F0F528B16256",1) -> =DISPIMG("ID_FCC82BBAA3A241A297D8F0F528B16256",1) | C3: B0FCMMBHGM | D3: 4PCS Wireless LED Lights for Car, 7 Colors Magnetic Auto Interior Light with Bright LED Lamp Beads, Portable Touch & USB Rechargeable Interior Lights, Easy Install for Car Decor (4PCS) | E3: =LEN(D3) -> 184 | F3: Portable Design: Measuring 1.06 x 2.09 inches, this car LED lights interior is small in size and lightweight, which is easy to carry and store. The multicolor LED car light has six high-brightness LEDs, providing bright and soft light to create an atmosphere. Rechargeable & Cord-Free: The led interior car lights charge with the USB cable, eliminating the need for batteries (2 cables are included in the package). These USB rechargeable car lights have the external USB connectors for charging, so you don't have to remove the housing. It takes about 1 hour to fully charge the light, which lasts for about 2-3 hours. Easy to Use: The wireless LED lights use touch control and light up with one touch. Press once to turn on the light and press and hold for three seconds to turn it off. There is one-click color change with a total of seven types of lights available. Note: Charge fully before first use. Wide Application: The car mood lights can be used in many places in the car, such as doors, windows, seat corners, above foot mats, handrails, storage bins, etc. It can also be used as a bedside lamp, wardrobe lamp, reading lamp or backpack lamp to illuminate dark places. Easy Installation: The magnetic rock lights offer two simple installation options. 1) Magnetic Mounting: Peel off the protective film from the magnetic plate and stick it to the back of the light. Then, remove the protective film from the double-sided adhesive and apply it to one side of the metal plate. Attach the metal plate to your desired position and mount the light onto it. 2) Adhesive Mounting: Use the double-sided tape to directly secure the light onto the desired surface. Note: For a stronger bond, clean and air-dry the surfaces before attaching. | G3: =LEN(F3) -> 1741 | H3: 便携设计：这款汽车LED灯尺寸为1.06×2.09英寸，体积小巧、重量轻盈，便于携带和收纳。该多色LED车灯配备六颗高亮度LED灯珠，能发出明亮而柔和的光线，营造出理想的车内氛围。 可充电且无需线缆：这款LED车内灯可通过USB线充电，无需使用电池（包装内包含两根USB线）。灯具配备外置USB充电接口，无需拆卸外壳即可充电。充满电约需1小时，续航时间约为2至3小时。 操作简便：这款无线LED灯采用触控式控制，轻触即可点亮。单次点击即可开启灯光，长按三秒即可关闭。支持一键变色功能，共提供七种灯光模式。注意：首次使用前请充满电。 广泛适用：汽车氛围灯可应用于车内多个位置，如车门、车窗、座椅角落、脚垫上方、扶手、储物格等。它还可作为床头灯、衣柜灯、阅读灯或背包灯，用于照亮昏暗区域。 简易安装：这款磁吸式岩石灯提供两种简便的安装方式。1）磁吸式安装：先撕下磁性板上的保护膜，将其粘贴在灯具背面；随后从双面胶上撕下保护膜，将其贴在金属板的一侧；将金属板固定在所需位置后，即可安装灯具。2）胶粘式安装：使用双面胶带将灯具直接固定在目标表面。注意：为确保更牢固的粘合效果，请在安装前清洁表面并自然晾干。 | K3: 标题 | L3: 4PCS Magnetic LED Interior Car Lights, 8 Colors Wireless Ambient Nightlight | M3: =LEN(L3) -> 75 | P3: 【8 Colors + 4 Dynamic Modes–Set the Mood】 – 8 vibrant colors: white, red, blue, green, purple, yellow, ice blue, and pink. 4 modes: fast flash for alerts, slow flash (SOS) for roadside assistance, steady on for daily use, and cycling warning. Non-glare design – bright enough to see, soft enough to drive. Perfect as car led interior lights or interior ambiance lighting for any vehicle. | Q3: =LEN(P3) -> 387 | R3: 【8种颜色 + 4种动态模式 – 营造氛围】 – 8种鲜艳颜色：白色、红色、蓝色、绿色、紫色、黄色、冰蓝色和粉色。4种模式：快闪用于警示，慢闪（SOS）用于路边救援，常亮用于日常使用，循环警示。不刺眼设计 – 够亮看得见，够柔不刺眼。 | T3: 第一点先改 | U3: 【Light Up Every Dark Corner of Your Car】 – Stop struggling with dark footwells, hidden storage areas, and back seats at night. These wireless magnetic LED interior car lights provide instant illumination wherever you need it – perfect for footwell, glove box, center console, door pocket, trunk, and more.
A4: 3 | B4: =_xlfn.DISPIMG("ID_DCFED7E880A0493787B6907174375450",1) -> =DISPIMG("ID_DCFED7E880A0493787B6907174375450",1) | C4: B0FRQBC873 | D4: 4PCS Car Interior Wireless Led Lights, 6 Bright LED Lamp Beads Magnetic Vehicle Ambient Light, Portable Touch USB Rechargeable Automotive Night Lighting Accessories, Universal Fit (Multicolor) | E4: =LEN(D4) -> 192 | F4: High Quality Material: This vehicle touch-sensitive ambient light is meticulously crafted from high-quality ABS, a material renowned for its exceptional durability and safety within automotive interiors. The ABS casing is lightweight yet robust, withstanding daily impacts without cracking, warping, or fading over extended use. Universal Size: This ambient light features a 1x2-inch miniature design, fitting seamlessly into saloons, SUVs, lorries, vans and other vehicle types. Its diminutive size allows installation in narrow, hard-to-reach recesses where traditional lighting struggles: within glove compartments, beneath armrests, in seat crevices or along door storage compartments. Easy Installation: Installation is swift and straightforward. First, secure the magnetic plate to your chosen location using double-sided tape. Next, attach the magnet to the base of the touch-sensitive light. Finally, snap the light onto the magnetic plate and press and hold the body to switch it on or off. The magnetic system enables swift removal and attachment, and can also be secured to other metal surfaces within the vehicle. Dual-Function Lighting: Featuring six high-brightness LED bulbs, this ambient light emits a soft, warm glow to create a comfortable cabin atmosphere. It alleviates eye strain during night-time driving, ensuring passengers feel thoroughly relaxed. Additionally, it provides precise task lighting with sufficient brightness to illuminate dark areas like the glove compartment and seat crevices, enabling easy retrieval of small items without activating the harsh overhead light. Package Includes: Presented in colourful packaging, the set includes 4 car ambient lights, 2 charging cable, 4 double-sided adhesive pad, 4 magnet, and 4 magnetic backing plate. Charge via the included USB cable: a full charge in 1 hour provides 2 hours of continuous use, with low-power LED bulbs ensuring efficient battery life. This four-piece set caters to all upgrade needs—whether enhancing convenience, boosting safety, or creating ambient lighting. | G4: =LEN(F4) -> 2059 | H4: 高品质材质：这款车辆触控式环境照明系统采用高品质ABS材料精心制造，该材料以其卓越的耐用性和安全性而闻名于汽车内饰领域。ABS外壳轻巧却坚固耐用，即使长期使用也不会出现开裂、变形或褪色现象。 通用尺寸：这款环境照明装置采用1×2英寸的迷你设计，可完美适配轿车、SUV、卡车、厢式货车及其他各类车辆。其小巧的体积使其能够安装在传统照明难以触及的狭窄角落——例如手套箱内、扶手下方、座椅缝隙处或车门储物格内。 安装简便：安装过程快速且简单。首先，使用双面胶将磁性板固定在选定位置；接着，将磁铁安装到触控灯的底座上；最后，将灯具扣合到磁性板上，并长按机身即可开关电源。该磁吸系统支持快速拆卸与安装，也可固定于车辆内的其他金属表面。 双功能照明系统：配备六颗高亮度LED灯泡，该环境照明散发出柔和温暖的光晕，营造出舒适的车内氛围。夜间驾驶时可有效缓解眼睛疲劳，让乘客感到彻底放松。此外，该系统还能提供精准的任务照明——亮度充足可照亮手套箱、座椅缝隙等昏暗区域，无需开启刺眼的顶灯即可轻松取用小物件。 产品包装包含：这套产品采用色彩鲜艳的包装设计，内含4个汽车氛围灯、2根充电线、4个双面粘贴垫、4个磁铁以及4块磁性背板。通过随附的USB线充电：充满电后1小时可连续使用2小时，低功耗LED灯泡可有效延长电池寿命。这套四件套产品能满足各类升级需求——无论是提升使用便捷性、增强安全性，还是营造氛围照明效果。 | K4: highlight | L4: USB Rechargeable Strobe Lighting with Remote & Touch Control, Vehicle Decor for Footwell Door Dash Glove Box – Car Truck SUV | M4: =LEN(L4) -> 124 | P4: 【Use Anywhere – Magnetic Lights for Car】 – Perfect for footwell, under dash, door pockets, glove box, center console, trunk, and cupholders. Works great as car LED interior lights or interior car light. Creates the perfect ambiance for night drives, road trips, or daily commutes. | Q4: =LEN(P4) -> 280 | R4: 【多场景适用 – 车载磁吸灯】 – 这些磁吸灯完美适配脚坑、仪表台下、门边储物格、手套箱、扶手箱、后备箱或杯架等。非常适合用作车内LED氛围灯或车内照明灯 – 为夜间驾驶、公路旅行或日常通勤营造完美氛围。 | U4: 【Wireless + Magnetic – Easy Installation】 – This magnetic LED light requires no drilling, no wiring, no tools. 4 SIMPLE STEPS: 01. Stick the adhesive pad to any surface in your car (floor mat, window side, glove box). 02. Attach the metal plate. 03. Stick the magnetic sticker to the light. 04. Snap the light onto the metal plate. Need to charge? Just pull it off and connect the USB charging cable.
L5: Attach Anywhere & Remove Anytime, Magnetic LED Lights w/Remote & Touch Control for Footwell, Door Pocket, Glove Box & Trunk | P5: 【Wireless + Magnetic – Easy Installation】 – This magnetic LED light requires no drilling, no wiring, no tools. Four simple steps: 1. Stick the adhesive pad to any surface in your car (floor mat, window side, glove box). 2. Attach the metal plate. 3. Stick the magnetic sticker to the light. 4. Snap the light onto the metal plate. Need to charge? Just pull it off and connect the USB charging cable. | Q5: =LEN(P5) -> 399 | R5: 【无线 + 磁吸 – 简易安装】 – 这款磁吸LED灯免钻孔、免接线、无需工具。四步轻松搞定：1. 将背胶粘贴到车内任意表面（脚垫、车窗边、手套箱）；2. 贴上铁片；3. 将磁吸片粘到灯上；4. 将灯吸附到铁片上。需要充电？取下连接USB充电线即可。 | U5: 【Touch+Wireless Remote – One Remote Syncs All Lamps】 – NOTE: The remote works only when the lamp has been manually turned on. Before each remote use, press the center of the lamp to turn it on. Operation: press center to on/off (long press 3s off; tap cycles 8 colors/modes). Once on, remote controls all lit lamps within 7m – one-click color, brightness, mode. USB: 1h charge, 10h use. For cars, trucks, RVs, wardrobes, etc.
A6: 4 | B6: =_xlfn.DISPIMG("ID_A59104AD5A964565A03B56751531475B",1) -> =DISPIMG("ID_A59104AD5A964565A03B56751531475B",1) | C6: B0FSKYWLNS | D6: 4PCS Wireless Car Led Ambient Lights, 7 Colors RGB Car Interior Light with Remote & Touch Control, Magnetic Rechargeable Type-C Mini LED Light for Cars, Cabinet, Wardrobe | E6: =LEN(D6) -> 170 | F6: UPGRADED REMOTE & TOUCH CONTROL – Control multiple lights with one remote, switch modes with one click, control range up to 7m. Touch control is also supported for flexible use in cars or at home 7 COLORS & 3 MODES – Equipped with 6 RGB LEDs, offering red, blue, green, yellow, pink, ice blue, white, plus breathing, gradient, and music sound-control modes. Long lifespan up to 50,000 hours MAGNETIC EASY INSTALLATION – No drilling or wiring needed. Attach the included magnetic plate to the back and fix on any iron surface. For non-metal surfaces, use the included iron plate with double-sided sticker adhesive to mount securely. TYPE-C CHARGING – Comes with a USB Type-C 1-to-4 cable to charge four lights at once. Built-in 150mAh battery fully charges in 40 minutes and provides up to 2 hours of lighting COMPACT & MULTI-PURPOSE – Small, lightweight, and space-saving. Perfect as car ambient light, glove box light, footwell light, reading lamp, or for home use in cabinets, wardrobes, and bookshelves. | G6: =LEN(F6) -> 1006 | H6: 升级版遥控触控系统——单遥控器控制多盏灯，一键切换模式，控制范围达7米。支持触控操作，适用于汽车或家庭场景的灵活使用；7种颜色/3种模式——配备6颗RGB LED灯珠，可呈现红、蓝、绿、黄、粉、冰蓝、白色等色彩，并支持呼吸光效、渐变效果及音乐声控模式；使用寿命长达50,000小时；磁吸式简易安装——无需钻孔或布线，将附赠的磁性板贴于背面即可固定在任何铁质表面；对于非金属表面，请使用附带的双面胶粘贴片进行牢固安装。 Type-C充电——配备USB Type-C 1至4转换线，可同时为四盏灯充电。内置150mAh电池，40分钟即可充满电，照明续航长达2小时。紧凑多功能——体积小巧、重量轻盈且节省空间，适用于汽车氛围灯、手套箱照明、仪表板照明、阅读灯，或家庭橱柜、衣柜及书架照明。 | K6: 父体 | L6: Wireless LED Lights for Car Interior, 8 Colors RGB Ambient Lighting | M6: =LEN(L6) -> 67 | P6: 【Touch + Wireless Remote – One Remote for All Lights】Control these magnetic lights in two ways: touch the lamp to change colors or modes (press and hold for 3 seconds to turn on/off), or use the wireless remote to control multiple lights from up to 7 meters away – perfect for drivers and passengers. USB rechargeable with a 1‑hour charge for up to 10 hours of use. Ideal for cars, trucks, RVs, closets, and more. | Q6: =LEN(P6) -> 413 | R6: 【触摸 + 无线遥控 – 一个遥控器控制所有灯】- 这款磁吸灯支持两种控制方式：轻触灯体即可切换颜色或模式（长按3秒开关机），或使用无线遥控器在最远7米范围内同时控制多个灯具——非常适合驾驶员和乘客使用。USB充电：充电1小时，可持续使用长达10小时。适用于汽车、卡车、房车、衣柜等更多场景 | U6: 【Use Anywhere – Magnetic Lights for Car】 – Perfect for footwell, under dash, door pockets, glove box, center console, trunk, and cupholders. Works great as car LED interior lights or interior car light. Creates the perfect ambiance for night drives, road trips, or daily commutes.
B7: =_xlfn.DISPIMG("ID_3B1EFDAC98114FB2970384C6FDC18B3C",1) -> =DISPIMG("ID_3B1EFDAC98114FB2970384C6FDC18B3C",1) | C7: B0FX7NXTR4 | D7: 4PCS Car Wireless Interior LED Lights, Magnetic USB Rechargeable 7 Colors Vehicle Ambient Light with 6 LED Lamp Beads, Portable Touch Automotive Nightlight, Universal for Vehicles | E7: =LEN(D7) -> 179 | F7: Illumination & 7-Color Ambience: The car LED light features 6 LED bulbs, providing bright yet non-glaring illumination. For daily use, it serves as a practical light source, effortlessly illuminating dark areas within the vehicle to help occupants locate items and inspect vehicle conditions, meeting basic lighting needs. Besides, it offers 7 distinct color lighting effects. When activated, it creates diverse ambiances inside the car, enhancing the driving experience with added enjoyment. Touch Control & Easy Operation: This car interior LED light features a touch-sensitive switch. Users simply tap the switch area to activate the light, ensuring simple and convenient operation. When switching light colors is needed, the process is quick and easy, enhancing usability and effortlessly adding a warm ambiance to the vehicle interior. Vast Compatibility: The car LED light measures 2.05 x 1.06 x 0.39". It is compatible with sedans, trucks, SUVs, RVs, and more. It offers versatile installation options, fitting well on floor mats, the ceiling, window sills, armrest compartments, and seat corners. Different mounting locations deliver distinct lighting and ambiance effects, better adapting to various in-car usage needs. Smooth Installation: Featuring a magnetic sticker design paired with automotive-grade adhesive backing, this LED light ensures easy installation and use. Simply attach the magnetic plate to your desired location, then snap the light onto it. It features a USB charging port, requiring only 40 minutes for a full charge. A single charge provides approximately 2 hours of continuous illumination and supports over 500 recharge cycles, meeting extended usage needs. Compact & Durable: This car interior LED light features a compact and sleek design, making it easy to carry and use without occupying excessive space inside the vehicle. It also facilitates convenient storage when not in use. Its integrated structure ensures strong sealing, delivering waterproof and dustproof performance. Durable and scratch-resistant, it maintains excellent functionality and appearance over extended use without damage or deformation. | G7: =LEN(F7) -> 2147 | H7: 照明与七色氛围效果：该汽车LED灯配备6颗LED灯珠，能提供明亮而不刺眼的照明效果。日常使用时，它可作为实用光源，轻松照亮车内昏暗区域，帮助乘客寻找物品并检查车辆状况，满足基本照明需求；同时支持七种不同的彩色灯光效果。开启后，可营造出多样的车内氛围，让驾驶体验更加愉悦。 触控操作与便捷使用：该汽车内饰LED灯配备触控开关。用户只需轻触开关区域即可点亮灯光，操作简单便捷。切换灯光颜色时过程快速简便，不仅提升了使用体验，还能轻松为车内营造出温馨氛围。 卓越兼容性：这款汽车LED灯尺寸为2.05×1.06×0.39英寸，适用于轿车、卡车、SUV、房车等多种车型。其安装方式灵活多样，可完美贴合地垫、车顶、窗台、扶手凹槽及座椅角落。不同的安装位置能营造出独特的照明效果与氛围感，更能满足不同车内使用需求。 安装便捷：该LED灯采用磁性贴纸设计，搭配汽车级粘合背衬，确保安装和使用极为简便。只需将磁性板贴在指定位置，再将灯具扣合即可。产品配备USB充电接口，充满电仅需40分钟；单次充电可提供约2小时连续照明时间，并支持超过500次充电循环，完全满足长期使用需求。 紧凑耐用：这款汽车内部LED灯采用紧凑时尚的设计，便于携带和使用，不会占用车内过多空间；不使用时也能轻松收纳。其一体化结构确保了出色的密封性能，具备防水防尘功能。产品耐用且抗刮擦，长期使用后仍能保持优异的功能性和外观，不会出现损坏或变形。 | K7: highlight | L7: USB Rechargeable Strobe Lighting with Remote & Touch Control | M7: =LEN(L7) -> 60 | P7: 【Compact & Durable-Fits Multiple Vehicle Types 】 – Size: 3.15" x 1.77" x 0.39". This compact LED interior light features a sleek, space-saving design – easy to carry and use without taking up space in your vehicle. Easily stores away when not in use. IP65 waterproof – easy to wipe clean. Perfect for cars, trucks, and SUVs. | Q7: =LEN(P7) -> 324 | R7: 【适配多种车型 – 紧凑耐用】 – 尺寸：3.15" x 1.77" x 0.39"。这款紧凑型LED车内灯采用时尚的节省空间设计 – 便于携带和使用，不占用车内空间。不使用时轻松收纳。IP65防水 – 方便擦拭清洁。完美适配轿车、卡车和SUV。 | U7: 【8 Colors + 4 Dynamic Modes–Set the Mood】 – 8 vibrant colors: white, red, blue, green, purple, yellow, ice blue, and pink. 4 modes: fast flash for alerts, slow flash (SOS) for roadside assistance, steady on for daily use, and cycling warning. Non-glare design – bright enough to see, soft enough to drive. Perfect as car led interior lights or interior ambiance lighting for any vehicle.
E8: =LEN(D8) -> 0 | K8: 8PCS | L8: 8PCS Magnetic Wireless Interior Car Lights, 8 Colors RGB Ambient Nightlight | M8: =LEN(L8) -> 75 | P8: Ever fumbled around in your dark car at night?<br> Dropped your keys under the seat? Looking for snacks your child spilled in the back? Need to grab a shopping bag from the trunk? These magnetic LED interior lights for car brighten every corner of your vehicle. With a non-glare design, they’re bright enough to see clearly but soft enough not to distract you while driving. No more guessing or reaching blindly.<br><br> Stay secure – even on bumpy roads.<br> Our magnetic mounting system is tested on real roads – speed bumps, potholes, and sudden stops won’t shake it loose. The lights attach firmly without drilling, wiring, or tools, and leave no marks when you remove them. You’ll never worry about them falling off mid-drive.<br><br> One hour charge. Ten hours of light.<br> The Type-C port works with nearly anything – car chargers, power banks, laptops, or USB adapters. A full charge takes just one hour and gives you up to 10 hours of continuous use. Charge once before a long road trip, and you’re covered for the whole weekend.<br><br> Made for real people, real drives.<br> This isn‘t just another set of car lights interior wireless. It’s designed for: Rideshare drivers (Uber/Lyft) – help passengers find door handles and floor space Parents – light up the back seat to find dropped toys or snacks Night-shift commuters – see the ground clearly when getting in and out Camping & outdoor lovers – pop it off and use it as a tent light or emergency light Whatever your drive looks like, these truck interior lights (perfect for SUVs and RVs too) make it safer and easier.<br><br> Small, tough, and built for your vehicle.<br> Each light measures just 3.15" × 1.77" × 0.39" – smaller than a pack of gum. When not in use, tuck them into a glove box, door pocket, or cup holder. IP65 waterproof with a sealed charging port cover, so spills and dust won’t ruin your lights. Spilled coffee? Just wipe it clean.<br><br> | Q8: =LEN(P8) -> 1930 | R8: 晚上开车，是不是经常摸黑找东西？ 掉在脚垫上的钥匙、后座散落的零食、后备箱里的购物袋——这款磁吸LED灯帮你照亮车内每一个角落。防眩光设计，亮而不刺眼。无论是找东西、帮孩子系安全带，还是夜间上下车，都能看得清清楚楚。 颠簸路面也稳稳不掉。 我们的磁吸系统经过真实路测，减速带、坑洼路面、急刹车都不会松动。安装不留痕迹，拿走也不伤内饰。不用再担心灯会在行驶中掉落。 充电一次，够用好几天。 Type-C接口，车载充电器、充电宝、笔记本都能充。1小时充满，续航10小时。长途自驾前充一次，整个周末都不用再管它。出门在外，随时都能补电。 专为真实人群设计。 无论你是： 网约车司机 —— 帮乘客找到门把手和脚部空间 带娃家长 —— 后座照明，找零食、找玩具不费眼 夜班通勤族 —— 安全上下车，看清脚下 露营爱好者 —— 取下当帐篷灯或应急灯用 这款灯都能让每一次驾驶更轻松、更安全。 小巧、耐用、专为车载。 每个灯尺寸仅 8cm × 4.5cm × 1cm，比一盒口香糖还小。不用时轻松塞进手套箱或杯架。IP65防水，充电口带密封盖，洒了水或咖啡？擦一下就干净了。 | T8: <br> <br><br>
E9: =LEN(D9) -> 0 | K9: highlight | L9: LED Rechargeable Strobe Lighting with Remote & Touch Control, Vehicle Decor for Footwell Door Dash Glove Box – Car Truck SUV | M9: =LEN(L9) -> 124 | N9: 产品描述
J10: A41105-SL-USFBA 4.3 16pcs 恶魔之眼 | K10: 16pcs | L10: 16pcs Magnetic Interior Car Lights, 8 Colors Wireless Ambient Nightlight | M10: =LEN(L10) -> 72 | P10: magnetic led interior lights car interior light wireless rgb 8 colors rechargeable touch remote control ip65 waterproof usb footwell door dash glove box truck suv night light ambient lighting car led lights interior magnetic interior lights for car | Q10: =LEN(P10) -> 248
L11: Rechargeable Strobe Lighting with Remote & Touch Control, Vehicle Decor for Footwell Door Dash Glove Box | M11: =LEN(L11) -> 104 | N11: ST
J12: A41104-SL-USFBA 4.3 18pcs 恶魔之眼 | K12: 18pcs | L12: 18pcs Wireless Lights for Car Interior, 8 Colors Ambient Nightlight | M12: =LEN(L12) -> 67
L13: Rechargeable Strobe Lighting with Remote & Touch Control, Vehicle Decor for Footwell Door Dash Glove Box | M13: =LEN(L13) -> 104

Sheet 9.3 文案优化
A1: 1. Larger Glow Area for a Premium Interior Look | L1: 1.Larger Soft Glow Surface — Premium Ambience, Less Glare | T1: 大面积
A2: Unlike small pinpoint car lights, these wireless ambient lights feature a larger lighting surface that spreads light more evenly across your interior. The softer glow feels cleaner, more modern, and closer to factory-style ambient lighting—perfect for drivers who want a premium interior vibe without expensive modifications. | L2: Unlike small LED bulbs that create harsh, scattered hotspots, our larger circular light panel spreads a smooth, even glow across your interior. The result is a more refined, factory-inspired look that adds a touch of elegance to every night drive. Bright enough to illuminate your cabin, yet soft enough to reduce harsh glare and keep your eyes comfortable while driving. | T2: =LEN(L2) -> 371
A3: 不同于普通小灯珠形成的刺眼光点，这款无线氛围灯采用更大发光面设计，让车内灯光覆盖更均匀、更柔和，视觉效果更接近原车氛围灯。非常适合想提升车内高级感、但不想高成本改装的用户。 | L3: 不同于普通小灯珠容易产生刺眼、分散的光点，我们采用更大发光面积的圆形柔光面板，让光线均匀、柔和地铺满整个车内。呈现更精致、更接近原车氛围灯的高级质感，为每一次夜间驾驶增添优雅氛围。亮度足以照亮车厢，同时减少刺眼眩光，让夜间驾驶更加舒适。
L4: 2. Attach Anywhere & Remove Anytime | T4: 免拆车无乱线：磁吸底座，一秒拆装
A5: 2. Magnetic Snap-On Design Makes Installation Easy | L5: No wiring, drilling, or complicated installation. Simply attach the adhesive base wherever you want the light, then magnetically snap the light securely into place. Once installed, you can remove it anytime for charging, repositioning, or portable use. Perfect for illuminating your glove box, door pocket, trunk, or other dark areas without permanent installation. | T5: =LEN(L5) -> 365
A6: No wiring, no drilling, no complicated setup. Simply stick the base and magnetically attach the light in seconds. The removable magnetic design also makes charging faster and more convenient without damaging your interior or removing adhesive every time. | L6: 无需布线、钻孔或复杂安装——只需将粘性底座粘贴在您想要安装灯具的任何位置，然后用磁吸力将灯具牢固固定即可。安装完成后，您可以随时取下灯具进行充电、重新定位或便携使用。非常适合为手套箱、车门内袋、后备箱或其他光线不足的区域提供照明，且无需进行永久性安装。
A7: 无需接线、无需打孔，也不用复杂安装。贴好底座后即可磁吸固定，几秒完成安装。磁吸可拆卸设计让日常充电更方便，不必反复撕胶，也不容易影响原车内饰。 | L7: 3. Smart Remote & Music Sync | T7: 智能遥控 & 音乐律动 | U7: Music-Sync Lights — Turn Up the Music, Light Up the Ride
L8: Control all your interior lights with one handheld remote. Enjoy 8 Colors, 4 Dynamic Modes, adjustable brightness, and up to 7m (23ft) wireless range. Use the remote to activate Music Sync Mode and let the lights sync to the beat of your music. You can also tap the light to switch colors or modes, or press and hold for 3 seconds to turn it on or off. | T8: =LEN(L8) -> 352 | U8: Let the lights react to the beat and surrounding sound, creating a dynamic atmosphere as you drive. Choose from 8 colors and 4 dynamic modes, including Sound-Activated Color Cycle, for night drives, road trips, date nights, and casual hangouts. Use the included remote to adjust colors, brightness, and modes, or tap the light for quick control.
A9: 3. Soft Ambient Lighting for Night Drives | L9: 一个手持遥控器即可轻松控制所有车内灯光。支持8种颜色、4种动态模式、亮度调节，以及最长7米（23英尺）的无线遥控距离。**使用遥控器开启音乐律动模式，让灯光随着音乐节奏同步变化。**同时支持触控操作，轻触即可切换颜色或模式，长按3秒即可开关灯。
A10: Create a relaxing atmosphere during nighttime commutes, road trips, rideshare driving, or weekend cruising. Choose from 8 RGB colors and multiple lighting modes to match your mood. Designed with soft, non-harsh lighting that adds visibility without distracting glare while driving. | L10: 4. Light Up Every Space — Add Comfort & Style Anywhere | T10: 照亮每个空间——随处增添舒适与格调
A11: 无论是夜间通勤、长途旅行、网约车接单还是周末夜驾，都能营造更舒适的车内氛围。支持8种RGB颜色及多种灯光模式，灯光柔和不刺眼，在增加氛围感的同时兼顾夜间照明体验。 | L11: Whether you're illuminating the footwell, door pocket, glove box, center console, or trunk, these lights brighten dark, overlooked spaces and make it easier to find what you need at night. At the same time, they add a warm, stylish glow to your interior—perfect for daily commutes, road trips, family outings, and weekend adventures. | T11: =LEN(L11) -> 333
L12: 无论是脚部空间、车门储物格、手套箱、中央扶手箱还是后备箱，都能将原本昏暗、容易被忽视的区域变得更加实用、舒适。夜间寻找物品时提供恰到好处的照明，同时营造温馨而时尚的车内氛围，让日常通勤、长途旅行、家庭出行和周末自驾都更有品质。
A13: 4. One Remote Controls Multiple Lights | L13: 5.Long-Lasting & Rechargeable — Ready for Every Drive | T13: 充电
A14: Adjust brightness, colors, and lighting effects with one compact remote. Easily control multiple lights together for a cleaner and more seamless setup. Ideal for footwells, center consoles, door pockets, trunks, cup holders, and back seat areas. | L14: Enjoy up to 10 hours of use on a full charge. The included 4-in-1 USB charging cable lets you charge all four lights at the same time, making recharging quick and convenient. Designed for everyday use, the removable lights are ready for nighttime driving, road trips, camping, tailgating, roadside stops, and quick tasks around the car.
A15: 通过一个遥控器即可调节颜色、亮度及灯光模式，可同时控制多盏灯，让车内灯光效果更统一。适用于脚窝、中控区域、车门储物槽、后备箱、杯架及后排空间。 | T15: =LEN(L14) -> 336
L16: 充满电最长可使用10小时。随附的一拖四USB充电线可同时为4个灯充电，无需逐个充电，更加快捷方便。专为日常使用而设计，可拆卸灯体适用于夜间驾驶、长途旅行、露营、尾门活动、路边临时停车以及车内外的临时照明需求。
A17: 5. Compact, Rechargeable & Multi-Purpose
A18: More than just car interior lights. Use them in closets, bedside storage areas, RVs, camping setups, or anywhere soft portable lighting is needed. USB rechargeable and easy to reposition anytime. A practical gift for car enthusiasts, first-time drivers, and anyone who enjoys upgrading their space.
A19: 不仅适用于汽车氛围照明，也可用于衣柜、床边储物区、房车或露营场景。USB充电设计方便日常使用，小巧便携，可随时调整位置。也是送给车主、新手司机或汽车爱好者的实用礼物。
A21: Product Description（产品描述）​
A22: Upgrade your car interior atmosphere in minutes—without expensive installation or messy wiring. These wireless magnetic car interior lights are designed with a larger glow surface that creates softer, wider, and more premium-looking ambient lighting inside your vehicle. Unlike small harsh LED dots, the lighting feels smoother and more natural for nighttime driving. Simply attach the lights anywhere you need extra atmosphere or visibility—footwells, center consoles, door pockets, trunks, glove boxes, or back seats. The magnetic removable design makes charging quick and hassle-free, while the wireless setup keeps your interior clean and uncluttered. Perfect for drivers who want an easy interior upgrade, a more relaxing nighttime driving experience, or a cleaner modern car vibe.
A27: 无需复杂改装，也不用凌乱布线，几分钟即可提升车内氛围。 这款无线磁吸车内氛围灯采用更大发光面设计，灯光覆盖更均匀、更柔和，整体效果更接近高级原车氛围灯。相比普通刺眼的小光点，夜晚视觉体验更舒适自然。 可自由安装于脚窝、中控、车门储物槽、后备箱、手套箱及后排区域，在提升氛围感的同时增加夜间照明体验。 磁吸可拆卸设计让日常充电更轻松，无线设计也让车内更整洁。 非常适合希望快速升级车内环境、喜欢夜驾氛围感，或想低成本提升车内质感的用户。

Sheet 9.14 图片优化 
A1: 文案 | C1: AI给的参考提示
A2: 1. Magnetic Mount — Attach Anywhere, Remove Anytime No wiring, drilling, or complicated installation. Simply secure the adhesive base where you want the light, then magnetically snap the light into place. Need to charge, reposition, or use it somewhere else? Just pull it off and take it with you. A flexible lighting solution for glove boxes, door pockets, trunks, and other dark areas. | B2: 磁吸安装——随处安装，随时取下 无需布线、钻孔或复杂安装。只需将粘贴底座固定在需要的位置，再将灯体磁吸到位即可。需要充电、调整位置或在其他地方使用时，直接取下即可随身携带。灵活适用于手套箱、车门储物格、后备箱及其他昏暗区域。 | C2: 副图2（磁吸拆卸充电图）磁吸随取充电 = 0难度安装 + 0杂乱线缆 画面布局：突出磁吸 特写镜头：磁吸力强，展示一只手轻松“摘下”灯体的动作，旁边配一个充电特写。 暗示“无需拆除背胶，无需拖线照明”。
A3: 2. Larger Light Area — Wider Glow, Softer Feel Unlike small LED bulbs that create harsh, concentrated hotspots, the larger circular light panel spreads a smooth, even glow across your car interior. Its wider-looking light coverage helps illuminate more of the surrounding area without the sharp, pinpoint effect of small lights. Enjoy a softer, more comfortable glow for night drives, daily commutes, and road trips. | B3: 更大发光面——更宽的光照，更柔和的感受 不同于容易产生刺眼、集中的光点式小型 LED 灯，更大的圆形发光面能够在车内形成更加平滑、均匀的光线。更宽范围的发光效果可以照亮周围更多区域，同时减少小型灯具常见的尖锐点状光感。为夜间驾驶、日常通勤和公路旅行带来更加柔和、舒适的灯光体验。 | C3: 副图 1（大覆盖卖点图）​：对比竞品单一方向的小亮点，直观呈现您大尺寸灯带来的宽广发光角（Wider Glow） 画面布局：左右对比图 设计目标：把“大尺寸”翻译成“照射效果好”。 左侧 (Others)：小灯珠，只照亮了脚垫上一块硬币大小的区域，光线生硬。 右侧 (Ours)：大面板，光线呈 120°铺开，照亮整个脚部空间，光线柔和。并做个灯体大小的细节对比
A4: 3.Music-Sync Lights — Let the Lights Move With the Music Turn up the music and let the lights react to the beat and surrounding sound. The Sound-Activated Color Cycle creates a dynamic light experience that changes with the rhythm, adding energy to night drives, road trips, date nights, and casual hangouts. No app or complicated setup needed—just play your music and enjoy the show. | B4: 音乐律动灯光——让灯光随音乐一起律动 打开音乐，让灯光随着节拍和周围声音产生变化。声音感应变色模式会随着音乐节奏动态改变灯光效果，为夜间驾驶、公路旅行、约会之夜和朋友聚会增添更多活力。无需 App 或复杂设置，只需播放音乐，即可享受动态灯光效果。 | C4: 副图 4-1：音乐声控体验图：情侣驾乘、浪漫城市夜景、音乐波形律动，柔和展现律动（Sound-Activated）功能，情绪价值输出，适合 Road Trip 场景。 画面布局：夜晚车内，情侣或朋友在欢笑。中控屏显示播放界面，灯光颜色与节奏波纹同步，同时放个遥控指出哪个是音控按键。 | D4: 副图4-2（氛围场景图）：女性占一部分，在高级夜驾场景凸显情绪价值。 年轻女性对“拆车安装”有天然的排斥，但对“精致氛围”有极高的追求。 画面布局：展示一位精致女性在光线柔和的车内补妆或使用手机，光效选用“冰蓝色”或“粉紫色”，画面色调偏高级感、干净。 | E4: 生成两张
A5: 4.Light Up Every Space — From Daily Drives to Weekend Adventures Illuminate footwells, door pockets, glove boxes, center consoles, and trunks to make dark, overlooked areas easier to see at night. The removable design also lets you take the light beyond the cabin for roadside stops, camping, tailgating, or other nearby tasks. One light, more ways to use it whenever and wherever you need extra illumination. | B5: 照亮每个空间——从日常驾驶到周末出行 照亮脚部空间、车门储物格、手套箱、中控台和后备箱等容易被忽略的昏暗区域，让夜间寻找物品更加方便。可拆卸设计还让你可以将灯带出车外，用于路边停车、露营、尾门聚会或其他临时照明需求。一盏灯，多种使用方式，在需要额外照明时随时随地使用。 | C5: 副图 5：多场景与便携性 (Versatility) 设计目标：提高客单价，暗示用户“你需要买多组”。 场景A：脚底环境光。 场景B：车门储物格找物照明。 场景C：后备箱应急照明（展示手拿灯作为临时电筒）。 场景D：露营棚里使用
A6: 5.Transform Your Car’s Ambience — 8 Colors & 4 Modes Transform the feel of your car in seconds with 8 colors and 4 lighting modes. Choose a soft, relaxing glow or switch to a more vibrant look with Cycling Color Change, Breathing, Marquee, or Sound-Activated Color Cycle. Use the included remote to change colors, adjust brightness, and switch modes from your seat, or tap the light for quick control. From everyday cruising to nights out, create an atmosphere that feels uniquely yours. | B6: 焕新车内氛围——8种颜色与4种灯光模式 只需几秒钟，就能通过 8 种颜色和 4 种灯光模式改变车内氛围。可以选择柔和放松的灯光，也可以通过循环变色、呼吸、跑马灯或声音感应变色打造更加充满活力的效果。使用随附遥控器即可坐在座位上切换颜色、调节亮度和模式，也可以直接触摸灯体快速控制。从日常驾驶到夜晚出行，随心打造独属于你的车内氛围。 | C6: 副图 3：动态模式四宫格，展示智能化与多样性 循环交替：完整保留多色展开重叠及环形箭头轮转动态，直观展示全色谱循环切换。 呼吸模式：展示单一高级色（如冰蓝）由暗转亮的轨迹，保留青蓝同心脉冲光晕与柔和呼吸波形。 走马灯马灯流动：灯珠本体芯片点亮并呈现多彩跑马流水轨迹 声控循环变色模式：配合音符小图标，展示光随律动，结合彩色音乐均衡声浪，光感克制柔和、不夸张。

Sheet 部分AI图
C2: =_xlfn.DISPIMG("ID_B123FBFF183C4E629F83A9D573401656",1) -> =DISPIMG("ID_B123FBFF183C4E629F83A9D573401656",1) | D2: 从亚马逊转化的角度看，这个产品真正值得放大的不是“我有多少颜色”，而是： 灯体更大 → 发光存在感更强 → 4种动态效果 → 可以跟着音乐变化 → 无线、随意安装 → 改变车内氛围 这条链路比“8 Colors”更有购买欲。 一、先说“女性消费者是不是更多” 我的判断：不能简单定义为“女性更多”，但这类产品确实有比较明显的女性/年轻女性消费潜力。 汽车 Interior Ambient Lights 的购买动机和传统汽车配件不太一样。 传统汽配更多是： 功能 → 性能 → 耐用 → 解决问题 而氛围灯更偏： 视觉 → 情绪 → 个性化 → 体验 → 装饰 所以它天然更容易吸引： 喜欢车内装饰的人 喜欢个性化车内空间的人 年轻消费者 喜欢 RGB / Mood Lighting 的消费者 经常夜间驾驶的人 喜欢音乐、氛围、拍摄车内内容的人 其中女性消费者当然是一个值得重点考虑的细分人群。 但我不会在Listing里直接写： For Women Women's Car Interior Lights 这反而会缩小受众。 因为男性消费者同样大量购买这类产品。 二、我更建议把产品定位成“Lifestyle Interior Lighting” 而不是： Automotive LED Light 这是两个完全不同的购买逻辑。 Automotive LED Light 消费者关注： Brightness Durability Installation Compatibility Interior Ambient Light 消费者关注： 好不好看 氛围感 能不能跟音乐互动 有没有动态效果 是否容易安装 能不能随时改变效果 晚上开起来效果怎么样 所以你的产品应该更偏向： CAR INTERIOR MOOD LIGHTING 而不是单纯： RGB CAR LIGHTS 三、你说的“音乐声控模式”反而是非常值得放大的 这个地方我之前理解得不够准确。 你现在的实际逻辑是： 通过遥控器开启音乐声控模式 → 灯光根据音乐/声音循环变色 那么这个功能就不是普通的： Sound Activated 而应该重点表达： MUSIC-SYNC LIGHTING 或者： SOUND-ACTIVATED COLOR CHANGING 如果产品确实是根据音乐节奏/声音变化，可以写： TURN ON MUSIC MODE & LET THE LIGHTS MOVE WITH THE SOUND 这就有明显的“体验感”。 四、而且我认为“音乐声控”应该排在8 Colors前面 现在重新给卖点排序，我会这样： 优先级 卖点 转化价值 1 Larger Lighting Area ⭐⭐⭐⭐⭐ 2 4 Dynamic Lighting Modes ⭐⭐⭐⭐⭐ 3 Music/Sound-Activated Color Changing ⭐⭐⭐⭐⭐ 4 Wireless + Easy Placement ⭐⭐⭐⭐ 5 Remote + Touch Control ⭐⭐⭐⭐ 6 8 Colors ⭐⭐ 你会发现： 8 Colors已经被我降到第6位。 因为： 8 Colors = “选择更多” 而： Music Sync = “体验完全不同” 消费者更容易为后者产生购买兴趣。 五、四种模式应该成为整个Listing的核心差异化 你现在这个产品实际上可以形成一个非常好的视觉卖点： 4 WAYS TO SET THE MOOD 然后： 01 — Alternating Cycle Colors Change in Sequence 02 — Breathing Mode Smooth Fade In & Fade Out 03 — Marquee Mode Moving Light Effect 04 — Music Sync Colors Change With Sound 尤其第四个： MUSIC SYNC 我会单独做成一张非常有视觉冲击力的图片。 比如车内夜间场景： 🎵 MUSIC ON ↓ 灯光跟着音乐变化 ↓ YOUR CAR. YOUR VIBE. 这比列： Red / Green / Blue / Purple... 更有购买欲。 六、“大灯体”+“动态模式”其实可以组合成一个非常强的卖点 这两个东西不要分开孤立讲。 因为真正的购买理由是： 大面积发光 + 动态变化 = 更明显的氛围效果 所以我非常推荐： LARGER LIGHTING AREA More Visible Glow for a More Immersive Interior 然后下面： 4 Dynamic Modes | Music Sync | Multiple Lighting Effects 这样消费者看到的是： “这个灯装在车里应该会比较有存在感。” 而不是： “哦，又一个8色RGB灯。” 七、如果针对女性消费者，我不会直接“女性化” 这是一个很关键的运营判断。 不要把页面设计成： ❌ Pink ❌ Cute ❌ For Girls ❌ Women's Car Accessories 因为这样会把大量男性消费者排除掉。 我会采用： “年轻、时尚、个性化、氛围感” 这种男女都能接受，但是女性也更容易产生情绪共鸣的表达。 比如： Make Every Drive Feel Different. Set the Mood for Every Drive. Your Car. Your Mood. Your Vibe. Turn Your Everyday Drive Into Your Own Space. 这些都很好。 八、我甚至会把“女性购买场景”融入图片，而不是文案里写女性 比如图片场景可以出现： 日常通勤 车内柔和灯光。 夜间开车 车内动态灯光。 听音乐 Music Sync。 周末出行 车内氛围。 拍摄车内内容 如果产品效果确实适合拍摄，可以展示车内视觉效果。 这样实际上会自然吸引： 女性 + 年轻消费者 + Lifestyle消费者 同时不会损失男性用户。 九、你这个产品的核心人群，我会这样划分 不是： 男性 vs 女性 而是： 第一人群：Interior Styling Enthusiasts 喜欢： 个性化车内空间 / 氛围灯 / 装饰 第二人群：Music & Night Drive Users 喜欢： 夜间驾驶 + 音乐 + 动态灯光 第三人群：Young/Lifestyle Drivers 购买动机： 让普通车内看起来更有感觉 第四人群：DIY Convenience Buyers 喜欢： 不拆车、不布线、自己就能安装 其中女性消费者会比较容易集中在第一、第二、第三类。 所以我不会说： “女性是你的主要用户。” 更准确的说法是： 这是一个偏Lifestyle、视觉和情绪体验的汽车产品，因此女性和年轻消费者具有较强的潜在购买吸引力。 十、这也会改变我之前对你Listing的整体建议 如果重新做，我会把第一屏的产品认知做成： LARGER LIGHTING AREA More Glow. More Mood. 然后第二核心： 4 DYNAMIC LIGHTING MODES Including Music-Sync Color Changing 第三： WIRELESS. MAGNETIC. EASY TO PLACE. 第四： REMOTE + TOUCH CONTROL 第五才是： 8 COLORS 这样整个Listing就从： “一个有8种颜色的汽车灯” 变成： “一个能够改变车内氛围、拥有更大光效和音乐互动效果，而且安装简单的汽车氛围灯。” 这个定位明显更有购买欲。 还有一个我认为很值得做的动作 如果你能把**2–3个主要竞品的完整图片（尤其是副图）**发给我，我可以直接帮你做一次 “竞品卖点拆解”：看他们现在在卖什么、哪些卖点已经同质化，然后把你的 **“大灯体 + 4模式 + Music Sync + 无线安装”重新排序，最终给你一套真正针对“自然点击高但自然转化低”**的： ① 核心卖点排序 → ② 主图/副图规划 → ③ 五点 → ④ A+ → ⑤ 标题 这样会比单独优化文案更准确。 那请给出具体的图片设计方案 可以。结合你现在这个 ASIN “自然点击不少，但自然转化差” 的情况，我不会单纯把副图做成“功能说明书”，而是要让客户进入详情页后，在前 3 张图里迅速完成： 看到差异 → 感受到效果 → 理解使用方式 → 产生购买欲。 而且你现在最有价值的差异化其实已经比较清楚： Larger Lighting Area + 4 Dynamic Modes + Music-Sync + Wireless/Magnetic Installation 8 Colors 降为辅助信息。 下面我按照 Amazon 主图 + 6张副图，给你一套可以直接交给设计师执行的方案。 一、先确定整套图片的视觉定位 我建议不要做成传统汽配风： 黑底 + 参数 + 一堆箭头 + 产品特写 而应该偏： Modern / Stylish / Lifestyle / Night Drive 因为这个产品卖的不是“维修功能”，而是： 让车内变得更有氛围、更有个性。 视觉上建议： 深色车内环境 夜间场景 灯光效果明显 产品主体清晰 少量文字 大标题突出利益点 不要满屏参数 二、Image 1：主图——不要大改，但必须解决4PCS/6PCS 你现在主图的方向其实是对的： 4个灯 + 不同颜色 + 遥控器 + 白色背景 这是比较容易获得点击的。 目前必须解决： 截图里出现： 4 Pack 但变体位置却显示： 6pcs 这个必须统一。 如果实际销售的是4PCS： 主图明确： 4 PACK 不要出现任何6PCS信息。 主图建议 产品摆放： 4个灯 + Remote 四个灯分别呈现不同颜色，但不要为了展示8色而塞太多颜色。 主标题如果图片允许展示产品信息，可以考虑： 4PCS MAGNETIC CAR INTERIOR LIGHTS 但Amazon主图本身不要添加营销文字、场景等违规元素，主图保持标准白底产品展示。 三、Image 2：整套图片最重要的一张 核心卖点： LARGER LIGHTING AREA 副标题： More Visible Glow for Your Car Interior 画面怎么做？ 不要直接放一个灯然后写： Large Light Area 这样很弱。 应该： 左边 放灯体正面大特写 用一个细线框标出： LARGE LIGHTING AREA 右边 放灯安装在： Footwell 的真实夜间效果。 形成： 灯体大 ↓ 发光面积明显 ↓ 车内氛围更有存在感 这张图的核心目的 消费者第一眼就应该产生： “这个灯看起来发光面积挺大的。” 而不是： “哦，又一个RGB灯。” 四、Image 3：核心差异化——4种动态模式 这是我认为最值得投入设计的一张图。 主标题： 4 DYNAMIC LIGHTING MODES 副标题： Change the Mood With Every Drive 四宫格设计 ① ALTERNATING CYCLE 视觉： 红 → 蓝 → 绿 → 红 文字： Colors Alternate in Sequence ② BREATHING MODE 视觉： 亮 → 暗 → 亮 文字： Smooth Fade In & Out ③ MARQUEE MODE 视觉： 几个灯光点形成移动轨迹 文字： Dynamic Moving Light Effect ④ MUSIC SYNC 这个做最大。 视觉： 🎵 Music waveform 下面是车内灯光跟随变化。 文字： Colors Change With Sound 这里特别注意 不要把四个模式写成非常技术化的： Mode 1 / Mode 2 / Mode 3 / Mode 4 应该让消费者一眼理解： “我买回来可以玩出4种不同效果。” 这才是购买价值。 五、Image 4：重点打 Music Sync 因为你进一步确认： 音乐声控模式需要通过遥控器开启 所以我建议单独拿一张图强化这个功能。 TURN ON MUSIC MODE. LET THE LIGHTS MOVE WITH THE SOUND. 下面小字： Use the Remote to Activate Music-Sync Lighting 画面 做一个非常有氛围感的夜间车内： 驾驶位 / 中控 / 脚窝都能看到灯光。 旁边放： Remote 并用一条简单路径： Remote → Music Mode → Dynamic Color Changes 这张图卖的不是“声控” 而是： 体验 让消费者脑子里出现一个画面： 晚上开车 放音乐 灯光跟着声音变化 车内氛围完全不一样 这个比： 8 Colors 有吸引力得多。 六、Image 5：无线安装——解决购买顾虑 前面3张已经完成： 差异化 + 氛围感 现在开始解决： “买回来麻烦不麻烦？” WIRELESS. MAGNETIC. EASY TO PLACE. 副标题： No Wiring. No Drilling. Place It Where You Want. 画面建议 采用一个3步骤流程图： STEP 1 PEEL 撕开胶贴保护膜。 STEP 2 PLACE 放到需要的位置。 STEP 3 LIGHT UP 开启灯光。 旁边展示几个安装位置： Footwell Under Dash Door Pocket Center Console 这一张的核心不是“磁铁” 而是： 我不用折腾汽车。 这是非常重要的转化理由。 七、Image 6：4PCS的价值——不要只说“4个” 这个地方非常容易浪费。 很多竞品会： 4PCS 然后结束。 我们应该让客户理解： 4 LIGHTS. MORE WAYS TO GLOW. 副标题： Light Multiple Interior Areas With One Set 画面 用一辆车的俯视/车内示意图。 四个灯分别： ① Front Footwell ② Passenger Footwell ③ Door / Console Area ④ Rear / Other Interior Area 具体位置要根据你的产品实际适用范围调整。 最重要的视觉： 四个灯同时亮。 让消费者产生： “一套就可以把几个位置一起做起来。” 而不是： “为什么我要买4个？” 八、Image 7：Remote + Touch + 颜色 这张放到最后，因为它属于辅助功能。 主标题： CONTROL THE MOOD YOUR WAY 副标题： Remote or Touch Control for Quick Changes 左边： REMOTE CONTROL 展示遥控器。 标注： Change Modes Switch Colors Activate Music Mode 前提是这些功能都确实由遥控器支持。 右边： TOUCH CONTROL 放灯体局部特写。 展示： Tap → Change 最下面小面积再放： 8 COLORS 而不是让8 Colors占据整张图。 例如： 8 Colors • Multiple Effects • Easy Control 这样就很好。 九、如果你有A+，我会再增加一张“情绪场景图” A+不要重复前面7张。 我会做： MAKE EVERY DRIVE FEEL DIFFERENT 下面三个场景： DAILY COMMUTE 日常通勤 NIGHT DRIVE 夜间驾驶 MUSIC TIME 听音乐 这里我会适度增加女性/年轻Lifestyle场景。 但不要写： For Women 而是通过人物和车内环境自然体现。 例如： 时尚年轻的女性驾驶场景 夜间城市 音乐 柔和车内灯光 这样女性消费者会产生代入感，同时不会把男性用户排除掉。 十、整套图片的“卖点顺序”最终应该是这样 我建议你让设计师严格按照这个顺序走： 图片 核心主题 目的 主图 4PCS + Product 获得点击 Image 2 Larger Lighting Area 建立差异 Image 3 4 Dynamic Modes 展示功能价值 Image 4 Music-Sync Lighting 制造购买欲 Image 5 Wireless + Magnetic 消除安装顾虑 Image 6 4 Lights / Multiple Areas 解释套装价值 Image 7 Remote + Touch + 8 Colors 补充功能 A+ Lifestyle / Night Drive 强化情绪购买 这个顺序和你现在的页面逻辑会有很大区别。 十一、尤其不要把“8 Colors”放到第二张图 这是我现在比较明确的建议。 你的产品现在如果第二张图写： 8 COLORS 消费者很容易想： “我的其他选择也有8色。” 差异化马上消失。 而如果第二张： LARGER LIGHTING AREA 第三张： 4 DYNAMIC LIGHTING MODES 第四张： MUSIC-SYNC LIGHTING 消费者会连续得到三个信息： “它发光面积更大。” “它有4种动态效果。” “还能跟声音变化。” 这才会产生： “这个产品好像比刚才看到的那个更有意思。” 十二、关于女性消费者，我会这样处理视觉 我不建议整套图片全部用“酷炫赛车/改装车”风格。 因为那会把产品限制在： Male Automotive Enthusiast 这个人群。 建议整个视觉做到： 50% Automotive 车内、脚窝、安装、产品 30% Lifestyle 夜间驾驶、音乐、氛围 20% Product Detail 灯体、遥控器、安装结构 这样会更符合： 女性 + 年轻消费者 + 普通车主 + 汽车改装用户 而不是只吸引传统汽车改装男性用户。 十三、还有一个非常关键的设计原则 你现在的产品图片千万不要出现： 功能堆砌 例如： 8 Colors 4 Modes Remote Touch Magnetic Wireless USB Adhesive Portable Easy Installation 全部塞到一张图。 这就是典型的： “参数海报” 而不是： “购买理由”。 我会让每一张图只回答一个购买问题： Image 2：为什么它看起来更有存在感？ → Larger Lighting Area Image 3：为什么它比普通RGB灯更有趣？ → 4 Dynamic Modes Image 4：有什么特别的使用体验？ → Music Sync Image 5：麻不麻烦？ → Wireless / Magnetic Image 6：为什么4个值得买？ → Multiple Interior Areas Image 7：好不好控制？ → Remote / Touch 这套逻辑更适合你目前这种**“已经有点击，但详情页说服力不足”**的ASIN。 如果让我给设计师一句最核心的要求 不要让客户看完7张图只记住“这是一个8色汽车灯”，而要让客户记住： “灯体更大、4种动态效果、还能跟音乐变化，而且不用布线，装起来很简单。” | E2: =_xlfn.DISPIMG("ID_01A7EAAB1B824AFF9C709EB216E57DFE",1) -> =DISPIMG("ID_01A7EAAB1B824AFF9C709EB216E57DFE",1)
A4: 副图 1（大覆盖卖点图）​：对比竞品单一方向的小亮点，直观呈现您大尺寸灯带来的宽广发光角（Wider Glow） 画面布局：左右对比图 设计目标：把“大尺寸”翻译成“照射效果好”。 左侧 (Others)：小灯珠，只照亮了脚垫上一块硬币大小的区域，光线生硬。 右侧 (Ours)：大面板，光线呈 120°铺开，照亮整个脚部空间，光线柔和。并做个灯体大小的细节对比 | B4: =_xlfn.DISPIMG("ID_53C3318C49304AB7B3C4D0F39425587D",1) -> =DISPIMG("ID_53C3318C49304AB7B3C4D0F39425587D",1) | C4: =_xlfn.DISPIMG("ID_CADC4FD40CFF4E6BB89D9CC3386C7585",1) -> =DISPIMG("ID_CADC4FD40CFF4E6BB89D9CC3386C7585",1) | D4: =_xlfn.DISPIMG("ID_13997AE6F6134A42A6F9AEB60D7EBB55",1) -> =DISPIMG("ID_13997AE6F6134A42A6F9AEB60D7EBB55",1) | E4: =_xlfn.DISPIMG("ID_D97775D3B2F6475196BE0C5CB176E916",1) -> =DISPIMG("ID_D97775D3B2F6475196BE0C5CB176E916",1)
A5: 副图2（磁吸拆卸充电图）磁吸随取充电 = 0难度安装 + 0杂乱线缆 画面布局：突出磁吸 特写镜头：磁吸力强，展示一只手轻松“摘下”灯体的动作，旁边配一个充电特写。 暗示“无需拆除背胶，无需拖线照明”。 | B5: =_xlfn.DISPIMG("ID_531C985C582F40EB8EF9D429CC28E4A7",1) -> =DISPIMG("ID_531C985C582F40EB8EF9D429CC28E4A7",1) | C5: =_xlfn.DISPIMG("ID_B19194E912FF47BF868252A7B2DF0950",1) -> =DISPIMG("ID_B19194E912FF47BF868252A7B2DF0950",1)
A7: 副图 3：动态模式四宫格，展示智能化与多样性 循环交替：完整保留多色展开重叠及环形箭头轮转动态，直观展示全色谱循环切换。 呼吸模式：展示单一高级色（如冰蓝）由暗转亮的轨迹，保留青蓝同心脉冲光晕与柔和呼吸波形。 走马灯马灯流动：灯珠本体芯片点亮并呈现多彩跑马流水轨迹 声控循环变色模式：配合音符小图标，展示光随律动，结合彩色音乐均衡声浪，光感克制柔和、不夸张。 | B7: =_xlfn.DISPIMG("ID_8733A4E8B0D64490A296A7C66830BA6C",1) -> =DISPIMG("ID_8733A4E8B0D64490A296A7C66830BA6C",1)
A8: 副图 4：音乐声控场景图：情侣驾乘、浪漫城市夜景、音乐波形律动，柔和展现律动（Sound-Activated）功能，情绪价值输出，适合 Road Trip 场景。 画面布局：夜晚车内，情侣或朋友在欢笑。中控屏显示播放界面，灯光颜色与节奏波纹同步，同时放个遥控指出哪个是音控按键。 | B8: =_xlfn.DISPIMG("ID_578A92CB31D84590A35B140D1369E22F",1) -> =DISPIMG("ID_578A92CB31D84590A35B140D1369E22F",1) | C8: =_xlfn.DISPIMG("ID_098D04A366B94C198C65003D653756C4",1) -> =DISPIMG("ID_098D04A366B94C198C65003D653756C4",1)
C9: https://www.amazon.com/Magnetic-Wireless-Rechargeable-Vehicle-Underglow/dp/B0H6RVN11R/ref=sr_1_17?crid=2S9EWX7QLDDOX&dib=eyJ2IjoiMSJ9.Npe7Ce167KvPmUmiUkjC877cfP_oGDGjgw1onrwIU1w8Ldu20lnsqvKDdac5DpiTiiBpO0RyjELGL6Ghzzb1URPJoFZIA9SZRLkAO1FCpryAOaRYxzvOnAow-zd1jIXi7ZfSY6o-8sgKCn2m2Zr151fm7yRvTw9578brVdaB62Q8hB_qJe3R1dEgmMXPOcSclE9-w5R6uNvQNXV_X5OduEvThbfOWEzXnylVwACzeKKbHSisFWIt05xwCU9c08TFvYhbWat2J1BTUr8OvlxWZjY4LTpbvikKvwhbJRAx48I.M3x7dedtLv5DRH0sJ95JqljEXF7Lrkh11OlcjuaYpho&dib_tag=se&keywords=Wireless%2BRechargeable%2BMagnetic%2BLED%2Blight&qid=1788416146&sprefix=wireless%2Brechargeable%2Bmagnetic%2Bled%2Blight%2Caps%2C654&sr=8-17&th=1 | D9: https://www.amazon.com/Wireless-Magnetic-Interior-Ambient-Lighting/dp/B0H6P6K849/ref=sr_1_31?crid=2S9EWX7QLDDOX&dib=eyJ2IjoiMSJ9.Npe7Ce167KvPmUmiUkjC877cfP_oGDGjgw1onrwIU1w8Ldu20lnsqvKDdac5DpiTiiBpO0RyjELGL6Ghzzb1URPJoFZIA9SZRLkAO1FCpryAOaRYxzvOnAow-zd1jIXi7ZfSY6o-8sgKCn2m2Zr151fm7yRvTw9578brVdaB62Q8hB_qJe3R1dEgmMXPOcSclE9-w5R6uNvQNXV_X5OduEvThbfOWEzXnylVwACzeKKbHSisFWIt05xwCU9c08TFvYhbWat2J1BTUr8OvlxWZjY4LTpbvikKvwhbJRAx48I.M3x7dedtLv5DRH0sJ95JqljEXF7Lrkh11OlcjuaYpho&dib_tag=se&keywords=Wireless%2BRechargeable%2BMagnetic%2BLED%2Blight&qid=1788416146&sprefix=wireless%2Brechargeable%2Bmagnetic%2Bled%2Blight%2Caps%2C654&sr=8-31&th=1
A10: 副图5（氛围场景图）：女性占一部分，在高级夜驾场景凸显情绪价值。 年轻女性对“拆车安装”有天然的排斥，但对“精致氛围”有极高的追求。 画面布局：展示一位精致女性在光线柔和的车内补妆或使用手机，光效选用“冰蓝色”或“粉紫色”，画面色调偏高级感、干净。
A11: 副图 6：多场景与便携性 (Versatility) 设计目标：提高客单价，暗示用户“你需要买多组”。 场景A：脚底环境光。 场景B：车门储物格找物照明。 场景C：后备箱应急照明（展示手拿灯作为临时电筒）。 场景D：露营棚里使用

Sheet 部分AI图 (2)
C1: Chatgpt
C2: https://web.tabbit.ai/share/chat/Ry7uTj26jPtt | F2: =_xlfn.DISPIMG("ID_B123FBFF183C4E629F83A9D573401656",1) -> =DISPIMG("ID_B123FBFF183C4E629F83A9D573401656",1) | G2: 从亚马逊转化的角度看，这个产品真正值得放大的不是“我有多少颜色”，而是： 灯体更大 → 发光存在感更强 → 4种动态效果 → 可以跟着音乐变化 → 无线、随意安装 → 改变车内氛围 这条链路比“8 Colors”更有购买欲。 一、先说“女性消费者是不是更多” 我的判断：不能简单定义为“女性更多”，但这类产品确实有比较明显的女性/年轻女性消费潜力。 汽车 Interior Ambient Lights 的购买动机和传统汽车配件不太一样。 传统汽配更多是： 功能 → 性能 → 耐用 → 解决问题 而氛围灯更偏： 视觉 → 情绪 → 个性化 → 体验 → 装饰 所以它天然更容易吸引： 喜欢车内装饰的人 喜欢个性化车内空间的人 年轻消费者 喜欢 RGB / Mood Lighting 的消费者 经常夜间驾驶的人 喜欢音乐、氛围、拍摄车内内容的人 其中女性消费者当然是一个值得重点考虑的细分人群。 但我不会在Listing里直接写： For Women Women's Car Interior Lights 这反而会缩小受众。 因为男性消费者同样大量购买这类产品。 二、我更建议把产品定位成“Lifestyle Interior Lighting” 而不是： Automotive LED Light 这是两个完全不同的购买逻辑。 Automotive LED Light 消费者关注： Brightness Durability Installation Compatibility Interior Ambient Light 消费者关注： 好不好看 氛围感 能不能跟音乐互动 有没有动态效果 是否容易安装 能不能随时改变效果 晚上开起来效果怎么样 所以你的产品应该更偏向： CAR INTERIOR MOOD LIGHTING 而不是单纯： RGB CAR LIGHTS 三、你说的“音乐声控模式”反而是非常值得放大的 这个地方我之前理解得不够准确。 你现在的实际逻辑是： 通过遥控器开启音乐声控模式 → 灯光根据音乐/声音循环变色 那么这个功能就不是普通的： Sound Activated 而应该重点表达： MUSIC-SYNC LIGHTING 或者： SOUND-ACTIVATED COLOR CHANGING 如果产品确实是根据音乐节奏/声音变化，可以写： TURN ON MUSIC MODE & LET THE LIGHTS MOVE WITH THE SOUND 这就有明显的“体验感”。 四、而且我认为“音乐声控”应该排在8 Colors前面 现在重新给卖点排序，我会这样： 优先级 卖点 转化价值 1 Larger Lighting Area ⭐⭐⭐⭐⭐ 2 4 Dynamic Lighting Modes ⭐⭐⭐⭐⭐ 3 Music/Sound-Activated Color Changing ⭐⭐⭐⭐⭐ 4 Wireless + Easy Placement ⭐⭐⭐⭐ 5 Remote + Touch Control ⭐⭐⭐⭐ 6 8 Colors ⭐⭐ 你会发现： 8 Colors已经被我降到第6位。 因为： 8 Colors = “选择更多” 而： Music Sync = “体验完全不同” 消费者更容易为后者产生购买兴趣。 五、四种模式应该成为整个Listing的核心差异化 你现在这个产品实际上可以形成一个非常好的视觉卖点： 4 WAYS TO SET THE MOOD 然后： 01 — Alternating Cycle Colors Change in Sequence 02 — Breathing Mode Smooth Fade In & Fade Out 03 — Marquee Mode Moving Light Effect 04 — Music Sync Colors Change With Sound 尤其第四个： MUSIC SYNC 我会单独做成一张非常有视觉冲击力的图片。 比如车内夜间场景： 🎵 MUSIC ON ↓ 灯光跟着音乐变化 ↓ YOUR CAR. YOUR VIBE. 这比列： Red / Green / Blue / Purple... 更有购买欲。 六、“大灯体”+“动态模式”其实可以组合成一个非常强的卖点 这两个东西不要分开孤立讲。 因为真正的购买理由是： 大面积发光 + 动态变化 = 更明显的氛围效果 所以我非常推荐： LARGER LIGHTING AREA More Visible Glow for a More Immersive Interior 然后下面： 4 Dynamic Modes | Music Sync | Multiple Lighting Effects 这样消费者看到的是： “这个灯装在车里应该会比较有存在感。” 而不是： “哦，又一个8色RGB灯。” 七、如果针对女性消费者，我不会直接“女性化” 这是一个很关键的运营判断。 不要把页面设计成： ❌ Pink ❌ Cute ❌ For Girls ❌ Women's Car Accessories 因为这样会把大量男性消费者排除掉。 我会采用： “年轻、时尚、个性化、氛围感” 这种男女都能接受，但是女性也更容易产生情绪共鸣的表达。 比如： Make Every Drive Feel Different. Set the Mood for Every Drive. Your Car. Your Mood. Your Vibe. Turn Your Everyday Drive Into Your Own Space. 这些都很好。 八、我甚至会把“女性购买场景”融入图片，而不是文案里写女性 比如图片场景可以出现： 日常通勤 车内柔和灯光。 夜间开车 车内动态灯光。 听音乐 Music Sync。 周末出行 车内氛围。 拍摄车内内容 如果产品效果确实适合拍摄，可以展示车内视觉效果。 这样实际上会自然吸引： 女性 + 年轻消费者 + Lifestyle消费者 同时不会损失男性用户。 九、你这个产品的核心人群，我会这样划分 不是： 男性 vs 女性 而是： 第一人群：Interior Styling Enthusiasts 喜欢： 个性化车内空间 / 氛围灯 / 装饰 第二人群：Music & Night Drive Users 喜欢： 夜间驾驶 + 音乐 + 动态灯光 第三人群：Young/Lifestyle Drivers 购买动机： 让普通车内看起来更有感觉 第四人群：DIY Convenience Buyers 喜欢： 不拆车、不布线、自己就能安装 其中女性消费者会比较容易集中在第一、第二、第三类。 所以我不会说： “女性是你的主要用户。” 更准确的说法是： 这是一个偏Lifestyle、视觉和情绪体验的汽车产品，因此女性和年轻消费者具有较强的潜在购买吸引力。 十、这也会改变我之前对你Listing的整体建议 如果重新做，我会把第一屏的产品认知做成： LARGER LIGHTING AREA More Glow. More Mood. 然后第二核心： 4 DYNAMIC LIGHTING MODES Including Music-Sync Color Changing 第三： WIRELESS. MAGNETIC. EASY TO PLACE. 第四： REMOTE + TOUCH CONTROL 第五才是： 8 COLORS 这样整个Listing就从： “一个有8种颜色的汽车灯” 变成： “一个能够改变车内氛围、拥有更大光效和音乐互动效果，而且安装简单的汽车氛围灯。” 这个定位明显更有购买欲。 还有一个我认为很值得做的动作 如果你能把**2–3个主要竞品的完整图片（尤其是副图）**发给我，我可以直接帮你做一次 “竞品卖点拆解”：看他们现在在卖什么、哪些卖点已经同质化，然后把你的 **“大灯体 + 4模式 + Music Sync + 无线安装”重新排序，最终给你一套真正针对“自然点击高但自然转化低”**的： ① 核心卖点排序 → ② 主图/副图规划 → ③ 五点 → ④ A+ → ⑤ 标题 这样会比单独优化文案更准确。 那请给出具体的图片设计方案 可以。结合你现在这个 ASIN “自然点击不少，但自然转化差” 的情况，我不会单纯把副图做成“功能说明书”，而是要让客户进入详情页后，在前 3 张图里迅速完成： 看到差异 → 感受到效果 → 理解使用方式 → 产生购买欲。 而且你现在最有价值的差异化其实已经比较清楚： Larger Lighting Area + 4 Dynamic Modes + Music-Sync + Wireless/Magnetic Installation 8 Colors 降为辅助信息。 下面我按照 Amazon 主图 + 6张副图，给你一套可以直接交给设计师执行的方案。 一、先确定整套图片的视觉定位 我建议不要做成传统汽配风： 黑底 + 参数 + 一堆箭头 + 产品特写 而应该偏： Modern / Stylish / Lifestyle / Night Drive 因为这个产品卖的不是“维修功能”，而是： 让车内变得更有氛围、更有个性。 视觉上建议： 深色车内环境 夜间场景 灯光效果明显 产品主体清晰 少量文字 大标题突出利益点 不要满屏参数 二、Image 1：主图——不要大改，但必须解决4PCS/6PCS 你现在主图的方向其实是对的： 4个灯 + 不同颜色 + 遥控器 + 白色背景 这是比较容易获得点击的。 目前必须解决： 截图里出现： 4 Pack 但变体位置却显示： 6pcs 这个必须统一。 如果实际销售的是4PCS： 主图明确： 4 PACK 不要出现任何6PCS信息。 主图建议 产品摆放： 4个灯 + Remote 四个灯分别呈现不同颜色，但不要为了展示8色而塞太多颜色。 主标题如果图片允许展示产品信息，可以考虑： 4PCS MAGNETIC CAR INTERIOR LIGHTS 但Amazon主图本身不要添加营销文字、场景等违规元素，主图保持标准白底产品展示。 三、Image 2：整套图片最重要的一张 核心卖点： LARGER LIGHTING AREA 副标题： More Visible Glow for Your Car Interior 画面怎么做？ 不要直接放一个灯然后写： Large Light Area 这样很弱。 应该： 左边 放灯体正面大特写 用一个细线框标出： LARGE LIGHTING AREA 右边 放灯安装在： Footwell 的真实夜间效果。 形成： 灯体大 ↓ 发光面积明显 ↓ 车内氛围更有存在感 这张图的核心目的 消费者第一眼就应该产生： “这个灯看起来发光面积挺大的。” 而不是： “哦，又一个RGB灯。” 四、Image 3：核心差异化——4种动态模式 这是我认为最值得投入设计的一张图。 主标题： 4 DYNAMIC LIGHTING MODES 副标题： Change the Mood With Every Drive 四宫格设计 ① ALTERNATING CYCLE 视觉： 红 → 蓝 → 绿 → 红 文字： Colors Alternate in Sequence ② BREATHING MODE 视觉： 亮 → 暗 → 亮 文字： Smooth Fade In & Out ③ MARQUEE MODE 视觉： 几个灯光点形成移动轨迹 文字： Dynamic Moving Light Effect ④ MUSIC SYNC 这个做最大。 视觉： 🎵 Music waveform 下面是车内灯光跟随变化。 文字： Colors Change With Sound 这里特别注意 不要把四个模式写成非常技术化的： Mode 1 / Mode 2 / Mode 3 / Mode 4 应该让消费者一眼理解： “我买回来可以玩出4种不同效果。” 这才是购买价值。 五、Image 4：重点打 Music Sync 因为你进一步确认： 音乐声控模式需要通过遥控器开启 所以我建议单独拿一张图强化这个功能。 TURN ON MUSIC MODE. LET THE LIGHTS MOVE WITH THE SOUND. 下面小字： Use the Remote to Activate Music-Sync Lighting 画面 做一个非常有氛围感的夜间车内： 驾驶位 / 中控 / 脚窝都能看到灯光。 旁边放： Remote 并用一条简单路径： Remote → Music Mode → Dynamic Color Changes 这张图卖的不是“声控” 而是： 体验 让消费者脑子里出现一个画面： 晚上开车 放音乐 灯光跟着声音变化 车内氛围完全不一样 这个比： 8 Colors 有吸引力得多。 六、Image 5：无线安装——解决购买顾虑 前面3张已经完成： 差异化 + 氛围感 现在开始解决： “买回来麻烦不麻烦？” WIRELESS. MAGNETIC. EASY TO PLACE. 副标题： No Wiring. No Drilling. Place It Where You Want. 画面建议 采用一个3步骤流程图： STEP 1 PEEL 撕开胶贴保护膜。 STEP 2 PLACE 放到需要的位置。 STEP 3 LIGHT UP 开启灯光。 旁边展示几个安装位置： Footwell Under Dash Door Pocket Center Console 这一张的核心不是“磁铁” 而是： 我不用折腾汽车。 这是非常重要的转化理由。 七、Image 6：4PCS的价值——不要只说“4个” 这个地方非常容易浪费。 很多竞品会： 4PCS 然后结束。 我们应该让客户理解： 4 LIGHTS. MORE WAYS TO GLOW. 副标题： Light Multiple Interior Areas With One Set 画面 用一辆车的俯视/车内示意图。 四个灯分别： ① Front Footwell ② Passenger Footwell ③ Door / Console Area ④ Rear / Other Interior Area 具体位置要根据你的产品实际适用范围调整。 最重要的视觉： 四个灯同时亮。 让消费者产生： “一套就可以把几个位置一起做起来。” 而不是： “为什么我要买4个？” 八、Image 7：Remote + Touch + 颜色 这张放到最后，因为它属于辅助功能。 主标题： CONTROL THE MOOD YOUR WAY 副标题： Remote or Touch Control for Quick Changes 左边： REMOTE CONTROL 展示遥控器。 标注： Change Modes Switch Colors Activate Music Mode 前提是这些功能都确实由遥控器支持。 右边： TOUCH CONTROL 放灯体局部特写。 展示： Tap → Change 最下面小面积再放： 8 COLORS 而不是让8 Colors占据整张图。 例如： 8 Colors • Multiple Effects • Easy Control 这样就很好。 九、如果你有A+，我会再增加一张“情绪场景图” A+不要重复前面7张。 我会做： MAKE EVERY DRIVE FEEL DIFFERENT 下面三个场景： DAILY COMMUTE 日常通勤 NIGHT DRIVE 夜间驾驶 MUSIC TIME 听音乐 这里我会适度增加女性/年轻Lifestyle场景。 但不要写： For Women 而是通过人物和车内环境自然体现。 例如： 时尚年轻的女性驾驶场景 夜间城市 音乐 柔和车内灯光 这样女性消费者会产生代入感，同时不会把男性用户排除掉。 十、整套图片的“卖点顺序”最终应该是这样 我建议你让设计师严格按照这个顺序走： 图片 核心主题 目的 主图 4PCS + Product 获得点击 Image 2 Larger Lighting Area 建立差异 Image 3 4 Dynamic Modes 展示功能价值 Image 4 Music-Sync Lighting 制造购买欲 Image 5 Wireless + Magnetic 消除安装顾虑 Image 6 4 Lights / Multiple Areas 解释套装价值 Image 7 Remote + Touch + 8 Colors 补充功能 A+ Lifestyle / Night Drive 强化情绪购买 这个顺序和你现在的页面逻辑会有很大区别。 十一、尤其不要把“8 Colors”放到第二张图 这是我现在比较明确的建议。 你的产品现在如果第二张图写： 8 COLORS 消费者很容易想： “我的其他选择也有8色。” 差异化马上消失。 而如果第二张： LARGER LIGHTING AREA 第三张： 4 DYNAMIC LIGHTING MODES 第四张： MUSIC-SYNC LIGHTING 消费者会连续得到三个信息： “它发光面积更大。” “它有4种动态效果。” “还能跟声音变化。” 这才会产生： “这个产品好像比刚才看到的那个更有意思。” 十二、关于女性消费者，我会这样处理视觉 我不建议整套图片全部用“酷炫赛车/改装车”风格。 因为那会把产品限制在： Male Automotive Enthusiast 这个人群。 建议整个视觉做到： 50% Automotive 车内、脚窝、安装、产品 30% Lifestyle 夜间驾驶、音乐、氛围 20% Product Detail 灯体、遥控器、安装结构 这样会更符合： 女性 + 年轻消费者 + 普通车主 + 汽车改装用户 而不是只吸引传统汽车改装男性用户。 十三、还有一个非常关键的设计原则 你现在的产品图片千万不要出现： 功能堆砌 例如： 8 Colors 4 Modes Remote Touch Magnetic Wireless USB Adhesive Portable Easy Installation 全部塞到一张图。 这就是典型的： “参数海报” 而不是： “购买理由”。 我会让每一张图只回答一个购买问题： Image 2：为什么它看起来更有存在感？ → Larger Lighting Area Image 3：为什么它比普通RGB灯更有趣？ → 4 Dynamic Modes Image 4：有什么特别的使用体验？ → Music Sync Image 5：麻不麻烦？ → Wireless / Magnetic Image 6：为什么4个值得买？ → Multiple Interior Areas Image 7：好不好控制？ → Remote / Touch 这套逻辑更适合你目前这种**“已经有点击，但详情页说服力不足”**的ASIN。 如果让我给设计师一句最核心的要求 不要让客户看完7张图只记住“这是一个8色汽车灯”，而要让客户记住： “灯体更大、4种动态效果、还能跟音乐变化，而且不用布线，装起来很简单。” | H2: =_xlfn.DISPIMG("ID_01A7EAAB1B824AFF9C709EB216E57DFE",1) -> =DISPIMG("ID_01A7EAAB1B824AFF9C709EB216E57DFE",1)
C3: Gemeni
B4: 副图 1（大覆盖卖点图）​：对比竞品单一方向的小亮点，直观呈现您大尺寸灯带来的宽广发光角（Wider Glow） 画面布局：左右对比图 设计目标：把“大尺寸”翻译成“照射效果好”。 左侧 (Others)：小灯珠，只照亮了脚垫上一块硬币大小的区域，光线生硬。 右侧 (Ours)：大面板，光线呈 120°铺开，照亮整个脚部空间，光线柔和。并做个灯体大小的细节对比 | C4: LARGER LIGHT. WIDER GLOW A Larger Light-Emitting Area Creates a Softer, More Noticeable Glow. OTHERS Small Light Area Focused, limited glow OURS Larger Light Area Wider, softer glow | D4: LARGER LIGHTING AREA More Visible Glow for Your Car Interior 英文文案：Wider Glow Area: Not Just a Tiny Spot 中文释义：更广的照明范围：不只是一个小光斑。 | F4: =_xlfn.DISPIMG("ID_53C3318C49304AB7B3C4D0F39425587D",1) -> =DISPIMG("ID_53C3318C49304AB7B3C4D0F39425587D",1) | G4: =_xlfn.DISPIMG("ID_CADC4FD40CFF4E6BB89D9CC3386C7585",1) -> =DISPIMG("ID_CADC4FD40CFF4E6BB89D9CC3386C7585",1) | H4: =_xlfn.DISPIMG("ID_13997AE6F6134A42A6F9AEB60D7EBB55",1) -> =DISPIMG("ID_13997AE6F6134A42A6F9AEB60D7EBB55",1) | I4: =_xlfn.DISPIMG("ID_D97775D3B2F6475196BE0C5CB176E916",1) -> =DISPIMG("ID_D97775D3B2F6475196BE0C5CB176E916",1)
B5: 副图2（磁吸拆卸充电图）磁吸随取充电 = 0难度安装 + 0杂乱线缆 画面布局：突出磁吸 特写镜头：磁吸力强，展示一只手轻松“摘下”灯体的动作，旁边配一个充电特写。 暗示“无需拆除背胶，无需拖线照明”。 | C5: 副图4（磁吸拆卸充电图）​：单手拆卸特写 + USB Type-C 连线直充，突出便利性，也是侧面凸出随处可安装和拆卸 | D5: MAGNETIC. INSTALL ONCE. MOVE ANYTIME. NO DRILLING • NO WIRING • NO HASSLE. | E5: =_xlfn.DISPIMG("ID_531C985C582F40EB8EF9D429CC28E4A7",1) -> =DISPIMG("ID_531C985C582F40EB8EF9D429CC28E4A7",1) | F5: =_xlfn.DISPIMG("ID_B19194E912FF47BF868252A7B2DF0950",1) -> =DISPIMG("ID_B19194E912FF47BF868252A7B2DF0950",1) | G5: =_xlfn.DISPIMG("ID_D373F30DCAA64C5C8892F1E5D66322A3",1) -> =DISPIMG("ID_D373F30DCAA64C5C8892F1E5D66322A3",1)
G6: 音乐声控模式
B7: 副图 3：动态模式四宫格，展示智能化与多样性 循环交替：完整保留多色展开重叠及环形箭头轮转动态，直观展示全色谱循环切换。 呼吸模式：展示单一高级色（如冰蓝）由暗转亮的轨迹，保留青蓝同心脉冲光晕与柔和呼吸波形。 走马灯马灯流动：灯珠本体芯片点亮并呈现多彩跑马流水轨迹 声控循环变色模式：配合音符小图标，展示光随律动，结合彩色音乐均衡声浪，光感克制柔和、不夸张。 | C7: 4种模式 Mode 1:（循环交替）：完整保留多色展开重叠及环形箭头轮转动态，直观展示全色谱循环切换。 Mode 2:（呼吸模式）：保留青蓝同心脉冲光晕与柔和呼吸波形。 Mode 3: 走马灯）：灯珠本体芯片点亮并呈现多彩跑马流水轨迹。 Mode 4: （声控循环变色模式）：结合彩色音乐均衡声浪，光感克制柔和、不夸张。 | D7: 4 LIGHTING MODES. ONE VIBE FOR EVERY DRIVE. Change the Mood With Every Drive.Switch Up the Light to Match Your Mood. 四种模式 CYCLING COLOR Colors Flow & Change BREATHING Soft, Slow Light Pulses MARQUEE Dynamic Moving Light SOUND-ACTIVATED COLOR CYCLE Colors React to Sound | E7: 4 DYNAMIC LIGHTING MODES Change the Mood With Every Drive 4 Dynamic Modes: One Light, Four Ways to Set the Mood. ALTERNATING CYCLE BREATHING MODE MARQUEE MODE MUSIC SYNC | F7: =_xlfn.DISPIMG("ID_8733A4E8B0D64490A296A7C66830BA6C",1) -> =DISPIMG("ID_8733A4E8B0D64490A296A7C66830BA6C",1) | G7: =_xlfn.DISPIMG("ID_BFD19F690AFC41FE9481A36AD0840C02",1) -> =DISPIMG("ID_BFD19F690AFC41FE9481A36AD0840C02",1)
B8: 副图 4：音乐声控体验图：情侣驾乘、浪漫城市夜景、音乐波形律动，柔和展现律动（Sound-Activated）功能，情绪价值输出，适合 Road Trip 场景。 画面布局：夜晚车内，情侣或朋友在欢笑。中控屏显示播放界面，灯光颜色与节奏波纹同步，同时放个遥控指出哪个是音控按键。 | C8: 情侣驾乘、浪漫城市夜景、音乐波形律动，柔和展现律动（Sound-Activated）功能。 | D8: TURN UP THE MUSIC. LIGHT UP THE RIDE. Let the Lights React to the Sound and Set the Mood. Music • Night Drives • Road Trips • Parties | E8: Feel the Rhythm of Every Night Drive | F8: =_xlfn.DISPIMG("ID_578A92CB31D84590A35B140D1369E22F",1) -> =DISPIMG("ID_578A92CB31D84590A35B140D1369E22F",1)
F9: https://www.amazon.com/Magnetic-Wireless-Rechargeable-Vehicle-Underglow/dp/B0H6RVN11R/ref=sr_1_17?crid=2S9EWX7QLDDOX&dib=eyJ2IjoiMSJ9.Npe7Ce167KvPmUmiUkjC877cfP_oGDGjgw1onrwIU1w8Ldu20lnsqvKDdac5DpiTiiBpO0RyjELGL6Ghzzb1URPJoFZIA9SZRLkAO1FCpryAOaRYxzvOnAow-zd1jIXi7ZfSY6o-8sgKCn2m2Zr151fm7yRvTw9578brVdaB62Q8hB_qJe3R1dEgmMXPOcSclE9-w5R6uNvQNXV_X5OduEvThbfOWEzXnylVwACzeKKbHSisFWIt05xwCU9c08TFvYhbWat2J1BTUr8OvlxWZjY4LTpbvikKvwhbJRAx48I.M3x7dedtLv5DRH0sJ95JqljEXF7Lrkh11OlcjuaYpho&dib_tag=se&keywords=Wireless%2BRechargeable%2BMagnetic%2BLED%2Blight&qid=1788416146&sprefix=wireless%2Brechargeable%2Bmagnetic%2Bled%2Blight%2Caps%2C654&sr=8-17&th=1 | G9: https://www.amazon.com/Wireless-Magnetic-Interior-Ambient-Lighting/dp/B0H6P6K849/ref=sr_1_31?crid=2S9EWX7QLDDOX&dib=eyJ2IjoiMSJ9.Npe7Ce167KvPmUmiUkjC877cfP_oGDGjgw1onrwIU1w8Ldu20lnsqvKDdac5DpiTiiBpO0RyjELGL6Ghzzb1URPJoFZIA9SZRLkAO1FCpryAOaRYxzvOnAow-zd1jIXi7ZfSY6o-8sgKCn2m2Zr151fm7yRvTw9578brVdaB62Q8hB_qJe3R1dEgmMXPOcSclE9-w5R6uNvQNXV_X5OduEvThbfOWEzXnylVwACzeKKbHSisFWIt05xwCU9c08TFvYhbWat2J1BTUr8OvlxWZjY4LTpbvikKvwhbJRAx48I.M3x7dedtLv5DRH0sJ95JqljEXF7Lrkh11OlcjuaYpho&dib_tag=se&keywords=Wireless%2BRechargeable%2BMagnetic%2BLED%2Blight&qid=1788416146&sprefix=wireless%2Brechargeable%2Bmagnetic%2Bled%2Blight%2Caps%2C654&sr=8-31&th=1
B10: 副图5（氛围场景图）：女性占一部分，在高级夜驾场景凸显情绪价值。 年轻女性对“拆车安装”有天然的排斥，但对“精致氛围”有极高的追求。 画面布局：展示一位精致女性在光线柔和的车内补妆或使用手机，光效选用“冰蓝色”或“粉紫色”，画面色调偏高级感、干净。
B11: 副图 6：多场景与便携性 (Versatility) 设计目标：提高客单价，暗示用户“你需要买多组”。 场景A：脚底环境光。 场景B：车门储物格找物照明。 场景C：后备箱应急照明（展示手拿灯作为临时电筒）。 场景D：露营棚里使用 | C11: LIGHT WHERE YOU NEED IT From everyday drives to unexpected moments, bring light wherever you need it. FOOTWELL DOOR POCKET TRUNK CAMPING | E11: 英文文案：More Than a Car Light: Use It Anywhere

Sheet SIF-竞对流量词
A1: 美国站点_B0GG3Q92LS_2026-05-26 导出时间: 2026-05-26 15:00 查询时间: 最近7天 查询条件: ASIN(B0GG3Q92LS)
A2: # | B2: 关键词 | C2: 排名 | E2: 翻译 | F2: 关键词效果类型 | G2: 全部流量占比 | H2: 全部流量变化 | I2: 全部流量变化贡献度 | J2: 自然流量占比 | K2: 自然流量变化 | L2: 自然流量变化贡献度 | M2: SP(常规)流量占比 | N2: SP(常规)流量变化 | O2: SP(常规)流量变化贡献度 | P2: SP(推荐)流量占比 | Q2: SP(推荐)流量变化 | R2: SP(推荐)流量变化贡献度 | S2: SB(常规)流量占比 | T2: SB(常规)流量变化 | U2: SB(常规)流量变化贡献度 | V2: SBV流量占比 | W2: SBV流量变化 | X2: SBV流量变化贡献度 | Y2: 曝光位置 | Z2: 自然流量得分 | AA2: 自然流量得分占比 | AB2: 广告流量得分 | AC2: 广告流量得分占比 | AD2: SP(常规)流量得分 | AE2: SP(常规)流量占比 | AF2: SP(推荐)流量得分 | AG2: SP(推荐)流量占比 | AH2: SB(常规)流量得分 | AI2: SB(常规)流量占比 | AJ2: SBV流量得分 | AK2: SBV流量占比 | AL2: 自然排名 | AM2: 自然排名详情 | AN2: 自然排名时间 | AO2: SP(常规)排名 | AP2: SP(常规)排名详情 | AQ2: SP(常规)排名时间 | AR2: SP(常规)排名对应的广告活动 | AS2: 周ABA排名 | AT2: 周搜索趋势 | AU2: 关键词更新时间 | AV2: 关键词建议竞价（固定·精准)最高 | AW2: 关键词建议竞价（固定·精准)推荐 | AX2: 关键词建议竞价（固定·精准)最低 | AY2: 关键词建议竞价（固定·词组)最高 | AZ2: 关键词建议竞价（固定·词组)推荐 | BA2: 关键词建议竞价（固定·词组)最低 | BB2: 关键词建议竞价（固定·广泛)最高 | BC2: 关键词建议竞价（固定·广泛)推荐 | BD2: 关键词建议竞价（固定·广泛)最低 | BE2: 关键词建议竞价（提降·精准)最高 | BF2: 关键词建议竞价（提降·精准)推荐 | BG2: 关键词建议竞价（提降·精准)最低 | BH2: 关键词建议竞价（提降·词组)最高 | BI2: 关键词建议竞价（提降·词组)推荐 | BJ2: 关键词建议竞价（提降·词组)最低 | BK2: 关键词建议竞价（提降·广泛)最高 | BL2: 关键词建议竞价（提降·广泛)推荐 | BM2: 关键词建议竞价（提降·广泛)最低 | BN2: 关键词点击转化率 | BO2: ABA TOP3集中度-点击 | BP2: ABA TOP3集中度-转化
A3: 1 | B3: ambient lighting car | C3: 27317 | E3: 汽车环境照明 | F3: [主要流量词] | G3: 0.33362469 | H3: 23.177015 | I3: 0.24316412 | J3: 0.45178466 | K3: 23.177015 | L3: 0.42014361 | Y3: 自然位 | Z3: 47.535263 | AA3: 1 | AB3: 0 | AC3: 0 | AD3: 0 | AE3: 0 | AF3: 0 | AG3: 0 | AH3: 0 | AI3: 0 | AJ3: 0 | AK3: 0 | AL3: 134 | AM3: p3,38/48 | AN3: 2026-05-21 | AS3: 27317 | AT3: 11196 | AU3: 2026-05-26 01:01:40 | AV3: 0.74 | AW3: 0.59 | AX3: 0.44 | AY3: 0.88 | AZ3: 0.73 | BA3: 0.56 | BB3: 0.88 | BC3: 0.66 | BD3: 0.55 | BE3: 0.44 | BF3: 0.35 | BG3: 0.32 | BH3: 0.52 | BI3: 0.43 | BJ3: 0.33 | BK3: 0.54 | BL3: 0.4 | BM3: 0.34 | BN3: 0.03801237 | BO3: 0.249 | BP3: 0.1544
